
CommandNotFoundError: Your shell has not been properly configured to use 'conda deactivate'.
To initialize your shell, run

    $ conda init <SHELL_NAME>

Currently supported shells are:
  - bash
  - fish
  - tcsh
  - xonsh
  - zsh
  - powershell

See 'conda init --help' for more information and options.

IMPORTANT: You may need to close and restart your shell after running 'conda init'.



CommandNotFoundError: Your shell has not been properly configured to use 'conda activate'.
To initialize your shell, run

    $ conda init <SHELL_NAME>

Currently supported shells are:
  - bash
  - fish
  - tcsh
  - xonsh
  - zsh
  - powershell

See 'conda init --help' for more information and options.

IMPORTANT: You may need to close and restart your shell after running 'conda init'.


/var/slurmd/spool/slurmd/job55663160/slurm_script: line 17: cd: /n/home07/hyitayew/Research/Summer: No such file or directory
  0%|          | 0/101547 [00:00<?, ?it/s]  0%|          | 6/101547 [00:00<33:35, 50.39it/s]  0%|          | 12/101547 [00:00<33:25, 50.63it/s]  0%|          | 14/101547 [00:19<33:25, 50.63it/s]  0%|          | 15/101547 [00:32<89:43:04,  3.18s/it]Traceback (most recent call last):
  File "/n/home07/hyitayew/Research/Summer 2023/experiments/Final_convolution_benchmark/100/script_0_18_100.py", line 29, in <module>
    model = ConvNet(5, 64, 9, 3, 5)
  File "/n/home07/hyitayew/Research/Summer 2023/experiments/Final_convolution_benchmark/100/script_0_18_100.py", line 23, in __init__
    self.conv = nn.Conv2d(in_channels, out_channels, kernel_size=kernel_size, stride=stride, padding=kernel_size//2, groups=groups)
  File "/n/home07/hyitayew/pytorch/torch/nn/modules/conv.py", line 450, in __init__
    super().__init__(
  File "/n/home07/hyitayew/pytorch/torch/nn/modules/conv.py", line 92, in __init__
    raise ValueError('out_channels must be divisible by groups')
ValueError: out_channels must be divisible by groups
  0%|          | 19/101547 [00:44<88:38:06,  3.14s/it]  0%|          | 20/101547 [01:08<153:52:30,  5.46s/it]Traceback (most recent call last):
  File "/n/home07/hyitayew/Research/Summer 2023/experiments/Final_convolution_benchmark/100/script_0_23_100.py", line 29, in <module>
    model = ConvNet(5, 64, 9, 3, 5)
  File "/n/home07/hyitayew/Research/Summer 2023/experiments/Final_convolution_benchmark/100/script_0_23_100.py", line 23, in __init__
    self.conv = nn.Conv2d(in_channels, out_channels, kernel_size=kernel_size, stride=stride, padding=kernel_size//2, groups=groups)
  File "/n/home07/hyitayew/pytorch/torch/nn/modules/conv.py", line 450, in __init__
    super().__init__(
  File "/n/home07/hyitayew/pytorch/torch/nn/modules/conv.py", line 92, in __init__
    raise ValueError('out_channels must be divisible by groups')
ValueError: out_channels must be divisible by groups
  0%|          | 24/101547 [01:19<125:59:47,  4.47s/it]  0%|          | 25/101547 [01:40<182:37:14,  6.48s/it]Traceback (most recent call last):
  File "/n/home07/hyitayew/Research/Summer 2023/experiments/Final_convolution_benchmark/100/script_0_28_100.py", line 29, in <module>
    model = ConvNet(5, 64, 9, 3, 5)
  File "/n/home07/hyitayew/Research/Summer 2023/experiments/Final_convolution_benchmark/100/script_0_28_100.py", line 23, in __init__
    self.conv = nn.Conv2d(in_channels, out_channels, kernel_size=kernel_size, stride=stride, padding=kernel_size//2, groups=groups)
  File "/n/home07/hyitayew/pytorch/torch/nn/modules/conv.py", line 450, in __init__
    super().__init__(
  File "/n/home07/hyitayew/pytorch/torch/nn/modules/conv.py", line 92, in __init__
    raise ValueError('out_channels must be divisible by groups')
ValueError: out_channels must be divisible by groups
  0%|          | 29/101547 [01:51<137:31:31,  4.88s/it]  0%|          | 35/101547 [01:51<73:09:15,  2.59s/it]   0%|          | 41/101547 [01:51<43:59:34,  1.56s/it]  0%|          | 47/101547 [01:51<28:09:25,  1.00it/s]  0%|          | 53/101547 [01:51<18:42:23,  1.51it/s]  0%|          | 59/101547 [01:51<12:44:38,  2.21it/s]  0%|          | 59/101547 [02:09<12:44:38,  2.21it/s]  0%|          | 60/101547 [02:17<63:58:28,  2.27s/it]Traceback (most recent call last):
  File "/n/home07/hyitayew/Research/Summer 2023/experiments/Final_convolution_benchmark/100/script_0_63_100.py", line 29, in <module>
    model = ConvNet(5, 64, 9, 3, 5)
  File "/n/home07/hyitayew/Research/Summer 2023/experiments/Final_convolution_benchmark/100/script_0_63_100.py", line 23, in __init__
    self.conv = nn.Conv2d(in_channels, out_channels, kernel_size=kernel_size, stride=stride, padding=kernel_size//2, groups=groups)
  File "/n/home07/hyitayew/pytorch/torch/nn/modules/conv.py", line 450, in __init__
    super().__init__(
  File "/n/home07/hyitayew/pytorch/torch/nn/modules/conv.py", line 92, in __init__
    raise ValueError('out_channels must be divisible by groups')
ValueError: out_channels must be divisible by groups
  0%|          | 64/101547 [02:26<65:32:01,  2.32s/it]  0%|          | 64/101547 [02:39<65:32:01,  2.32s/it]  0%|          | 65/101547 [02:45<109:49:47,  3.90s/it]Traceback (most recent call last):
  File "/n/home07/hyitayew/Research/Summer 2023/experiments/Final_convolution_benchmark/100/script_0_68_100.py", line 29, in <module>
    model = ConvNet(5, 64, 9, 3, 5)
  File "/n/home07/hyitayew/Research/Summer 2023/experiments/Final_convolution_benchmark/100/script_0_68_100.py", line 23, in __init__
    self.conv = nn.Conv2d(in_channels, out_channels, kernel_size=kernel_size, stride=stride, padding=kernel_size//2, groups=groups)
  File "/n/home07/hyitayew/pytorch/torch/nn/modules/conv.py", line 450, in __init__
    super().__init__(
  File "/n/home07/hyitayew/pytorch/torch/nn/modules/conv.py", line 92, in __init__
    raise ValueError('out_channels must be divisible by groups')
ValueError: out_channels must be divisible by groups
  0%|          | 69/101547 [02:56<97:00:03,  3.44s/it]   0%|          | 70/101547 [03:09<126:45:51,  4.50s/it]Traceback (most recent call last):
  File "/n/home07/hyitayew/Research/Summer 2023/experiments/Final_convolution_benchmark/100/script_0_73_100.py", line 29, in <module>
    model = ConvNet(5, 64, 9, 3, 5)
  File "/n/home07/hyitayew/Research/Summer 2023/experiments/Final_convolution_benchmark/100/script_0_73_100.py", line 23, in __init__
    self.conv = nn.Conv2d(in_channels, out_channels, kernel_size=kernel_size, stride=stride, padding=kernel_size//2, groups=groups)
  File "/n/home07/hyitayew/pytorch/torch/nn/modules/conv.py", line 450, in __init__
    super().__init__(
  File "/n/home07/hyitayew/pytorch/torch/nn/modules/conv.py", line 92, in __init__
    raise ValueError('out_channels must be divisible by groups')
ValueError: out_channels must be divisible by groups
  0%|          | 74/101547 [03:18<102:15:06,  3.63s/it]  0%|          | 80/101547 [03:18<56:00:41,  1.99s/it]   0%|          | 86/101547 [03:18<34:10:23,  1.21s/it]  0%|          | 92/101547 [03:18<22:04:18,  1.28it/s]  0%|          | 98/101547 [03:18<14:45:52,  1.91it/s]  0%|          | 104/101547 [03:18<10:07:24,  2.78it/s]  0%|          | 104/101547 [03:30<10:07:24,  2.78it/s]  0%|          | 105/101547 [03:40<54:12:51,  1.92s/it]Traceback (most recent call last):
  File "/n/home07/hyitayew/Research/Summer 2023/experiments/Final_convolution_benchmark/100/script_0_108_100.py", line 29, in <module>
    model = ConvNet(5, 64, 9, 3, 5)
  File "/n/home07/hyitayew/Research/Summer 2023/experiments/Final_convolution_benchmark/100/script_0_108_100.py", line 23, in __init__
    self.conv = nn.Conv2d(in_channels, out_channels, kernel_size=kernel_size, stride=stride, padding=kernel_size//2, groups=groups)
  File "/n/home07/hyitayew/pytorch/torch/nn/modules/conv.py", line 450, in __init__
    super().__init__(
  File "/n/home07/hyitayew/pytorch/torch/nn/modules/conv.py", line 92, in __init__
    raise ValueError('out_channels must be divisible by groups')
ValueError: out_channels must be divisible by groups
  0%|          | 109/101547 [03:49<55:29:18,  1.97s/it]  0%|          | 109/101547 [04:00<55:29:18,  1.97s/it]  0%|          | 110/101547 [04:11<108:59:35,  3.87s/it]Traceback (most recent call last):
  File "/n/home07/hyitayew/Research/Summer 2023/experiments/Final_convolution_benchmark/100/script_0_113_100.py", line 29, in <module>
    model = ConvNet(5, 64, 9, 3, 5)
  File "/n/home07/hyitayew/Research/Summer 2023/experiments/Final_convolution_benchmark/100/script_0_113_100.py", line 23, in __init__
    self.conv = nn.Conv2d(in_channels, out_channels, kernel_size=kernel_size, stride=stride, padding=kernel_size//2, groups=groups)
  File "/n/home07/hyitayew/pytorch/torch/nn/modules/conv.py", line 450, in __init__
    super().__init__(
  File "/n/home07/hyitayew/pytorch/torch/nn/modules/conv.py", line 92, in __init__
    raise ValueError('out_channels must be divisible by groups')
ValueError: out_channels must be divisible by groups
  0%|          | 114/101547 [04:22<98:05:02,  3.48s/it] --- Logging error ---
Traceback (most recent call last):
  File "/n/home07/hyitayew/Research/Summer 2023/experiments/Final_convolution_benchmark/100/script_0_114_100.py", line 70, in <module>
  File "/n/home07/hyitayew/pytorch/torch/nn/modules/module.py", line 1501, in _call_impl
    return forward_call(*args, **kwargs)
  File "/n/home07/hyitayew/pytorch/torch/_dynamo/eval_frame.py", line 280, in _fn
    return fn(*args, **kwargs)
  File "/n/home07/hyitayew/pytorch/torch/nn/modules/module.py", line 1501, in _call_impl
    return forward_call(*args, **kwargs)
  File "/n/home07/hyitayew/pytorch/torch/_dynamo/eval_frame.py", line 433, in catch_errors
    return callback(frame, cache_size, hooks, frame_state)
  File "/n/home07/hyitayew/pytorch/torch/_dynamo/convert_frame.py", line 501, in _convert_frame
    result = inner_convert(frame, cache_size, hooks, frame_state)
  File "/n/home07/hyitayew/pytorch/torch/_dynamo/convert_frame.py", line 122, in _fn
    return fn(*args, **kwargs)
  File "/n/home07/hyitayew/pytorch/torch/_dynamo/convert_frame.py", line 337, in _convert_frame_assert
    return _compile(
  File "/n/home07/hyitayew/pytorch/torch/_dynamo/utils.py", line 177, in time_wrapper
    r = func(*args, **kwargs)
  File "/n/home07/hyitayew/pytorch/torch/_dynamo/convert_frame.py", line 407, in _compile
    out_code = transform_code_object(code, transform)
  File "/n/home07/hyitayew/pytorch/torch/_dynamo/bytecode_transformation.py", line 1000, in transform_code_object
    transformations(instructions, code_options)
  File "/n/home07/hyitayew/pytorch/torch/_dynamo/convert_frame.py", line 392, in transform
    tracer.run()
  File "/n/home07/hyitayew/pytorch/torch/_dynamo/symbolic_convert.py", line 2006, in run
    super().run()
  File "/n/home07/hyitayew/pytorch/torch/_dynamo/symbolic_convert.py", line 703, in run
    and self.step()
  File "/n/home07/hyitayew/pytorch/torch/_dynamo/symbolic_convert.py", line 663, in step
    getattr(self, inst.opname)(inst)
  File "/n/home07/hyitayew/pytorch/torch/_dynamo/symbolic_convert.py", line 2094, in RETURN_VALUE
    self.output.compile_subgraph(
  File "/n/home07/hyitayew/pytorch/torch/_dynamo/output_graph.py", line 673, in compile_subgraph
    self.compile_and_call_fx_graph(tx, list(reversed(stack_values)), root)
  File "/n/home07/hyitayew/source_env/lib/python3.10/contextlib.py", line 79, in inner
    return func(*args, **kwds)
  File "/n/home07/hyitayew/pytorch/torch/_dynamo/output_graph.py", line 772, in compile_and_call_fx_graph
    compiled_fn = self.call_user_compiler(gm)
  File "/n/home07/hyitayew/pytorch/torch/_dynamo/utils.py", line 177, in time_wrapper
    r = func(*args, **kwargs)
  File "/n/home07/hyitayew/pytorch/torch/_dynamo/output_graph.py", line 831, in call_user_compiler
    raise BackendCompilerFailed(self.compiler_fn, e).with_traceback(
  File "/n/home07/hyitayew/pytorch/torch/_dynamo/output_graph.py", line 827, in call_user_compiler
    compiled_fn = compiler_fn(gm, self.example_inputs())
  File "/n/home07/hyitayew/pytorch/torch/_dynamo/repro/after_dynamo.py", line 109, in debug_wrapper
    compiled_gm = compiler_fn(gm, example_inputs)
  File "/n/home07/hyitayew/pytorch/torch/__init__.py", line 1530, in __call__
    return compile_fx(model_, inputs_, config_patches=self.config)
  File "/n/home07/hyitayew/pytorch/torch/_inductor/compile_fx.py", line 795, in compile_fx
    return aot_autograd(
  File "/n/home07/hyitayew/pytorch/torch/_dynamo/backends/common.py", line 56, in compiler_fn
    cg = aot_module_simplified(gm, example_inputs, **kwargs)
  File "/n/home07/hyitayew/pytorch/torch/_functorch/aot_autograd.py", line 3332, in aot_module_simplified
    compiled_fn = create_aot_dispatcher_function(
  File "/n/home07/hyitayew/pytorch/torch/_dynamo/utils.py", line 177, in time_wrapper
    r = func(*args, **kwargs)
  File "/n/home07/hyitayew/pytorch/torch/_functorch/aot_autograd.py", line 2973, in create_aot_dispatcher_function
    compiled_fn = compiler_fn(flat_fn, fake_flat_args, aot_config, fw_metadata=fw_metadata)
  File "/n/home07/hyitayew/pytorch/torch/_functorch/aot_autograd.py", line 1911, in aot_wrapper_dedupe
    return compiler_fn(flat_fn, leaf_flat_args, aot_config, fw_metadata=fw_metadata)
  File "/n/home07/hyitayew/pytorch/torch/_functorch/aot_autograd.py", line 2080, in aot_wrapper_synthetic_base
    return compiler_fn(flat_fn, flat_args, aot_config, fw_metadata=fw_metadata)
  File "/n/home07/hyitayew/pytorch/torch/_functorch/aot_autograd.py", line 2569, in aot_dispatch_autograd
    compiled_fw_func = aot_config.fw_compiler(
  File "/n/home07/hyitayew/pytorch/torch/_dynamo/utils.py", line 177, in time_wrapper
    r = func(*args, **kwargs)
  File "/n/home07/hyitayew/pytorch/torch/_inductor/compile_fx.py", line 751, in fw_compiler_base
    return inner_compile(
  File "/n/home07/hyitayew/pytorch/torch/_dynamo/repro/after_aot.py", line 73, in debug_wrapper
    inner_compiled_fn = compiler_fn(gm, example_inputs)
  File "/n/home07/hyitayew/pytorch/torch/_inductor/debug.py", line 220, in inner
    return fn(*args, **kwargs)
  File "/n/home07/hyitayew/source_env/lib/python3.10/contextlib.py", line 79, in inner
    return func(*args, **kwds)
  File "/n/home07/hyitayew/pytorch/torch/_inductor/compile_fx.py", line 265, in compile_fx_inner
    compiled_fn = graph.compile_to_fn()
  File "/n/home07/hyitayew/pytorch/torch/_inductor/graph.py", line 728, in compile_to_fn
    return self.compile_to_module().call
  File "/n/home07/hyitayew/pytorch/torch/_dynamo/utils.py", line 177, in time_wrapper
    r = func(*args, **kwargs)
  File "/n/home07/hyitayew/pytorch/torch/_inductor/graph.py", line 696, in compile_to_module
    code, linemap = self.codegen()
  File "/n/home07/hyitayew/pytorch/torch/_inductor/graph.py", line 645, in codegen
    self.scheduler.codegen()
  File "/n/home07/hyitayew/pytorch/torch/_dynamo/utils.py", line 177, in time_wrapper
    r = func(*args, **kwargs)
  File "/n/home07/hyitayew/pytorch/torch/_inductor/scheduler.py", line 1360, in codegen
    write_data(node_data)
  File "/n/home07/hyitayew/pytorch/torch/_inductor/scheduler.py", line 1357, in write_data
    with open(f"Data_{benchmark.filename}.json", "w") as f:
torch._dynamo.exc.BackendCompilerFailed: backend='inductor' raised:
OSError: [Errno 116] Stale file handle: 'Data_.json'


You can suppress this exception and fall back to eager by setting:
    import torch._dynamo
    torch._dynamo.config.suppress_errors = True


During handling of the above exception, another exception occurred:

Traceback (most recent call last):
  File "/n/home07/hyitayew/source_env/lib/python3.10/site-packages/concurrent_log_handler/__init__.py", line 293, in atomic_open
    file = open(file_path, "r+", encoding=self.encoding, newline=self.newline)
FileNotFoundError: [Errno 2] No such file or directory: '/n/home07/hyitayew/Research/Summer 2023/experiments/Final_convolution_benchmark/100/.__benchmark_convolution.lock'

During handling of the above exception, another exception occurred:

Traceback (most recent call last):
  File "/n/home07/hyitayew/source_env/lib/python3.10/site-packages/concurrent_log_handler/__init__.py", line 382, in emit
    self._do_lock()
  File "/n/home07/hyitayew/source_env/lib/python3.10/site-packages/concurrent_log_handler/__init__.py", line 434, in _do_lock
    self._open_lockfile()
  File "/n/home07/hyitayew/source_env/lib/python3.10/site-packages/concurrent_log_handler/__init__.py", line 286, in _open_lockfile
    self.stream_lock = self.atomic_open(lock_file)
  File "/n/home07/hyitayew/source_env/lib/python3.10/site-packages/concurrent_log_handler/__init__.py", line 297, in atomic_open
    fd = os.open(file_path, os.O_CREAT | os.O_EXCL | os.O_RDWR)
FileNotFoundError: [Errno 2] No such file or directory: '/n/home07/hyitayew/Research/Summer 2023/experiments/Final_convolution_benchmark/100/.__benchmark_convolution.lock'
Call stack:
  File "/n/home07/hyitayew/Research/Summer 2023/experiments/Final_convolution_benchmark/100/script_0_114_100.py", line 79, in <module>
  File "/n/home07/hyitayew/source_env/lib/python3.10/logging/__init__.py", line 1506, in error
    self._log(ERROR, msg, args, **kwargs)
  File "/n/home07/hyitayew/source_env/lib/python3.10/logging/__init__.py", line 1624, in _log
    self.handle(record)
  File "/n/home07/hyitayew/source_env/lib/python3.10/logging/__init__.py", line 1634, in handle
    self.callHandlers(record)
  File "/n/home07/hyitayew/source_env/lib/python3.10/logging/__init__.py", line 1696, in callHandlers
    hdlr.handle(record)
  File "/n/home07/hyitayew/source_env/lib/python3.10/logging/__init__.py", line 968, in handle
    self.emit(record)
  File "/n/home07/hyitayew/source_env/lib/python3.10/site-packages/concurrent_log_handler/__init__.py", line 400, in emit
    self.handleError(record)
Message: "There was an exception running the following parameters: 64, 5, 64, 9, 3, 3900, 6103, external on gpu:0\nbackend='inductor' raised:\nOSError: [Errno 116] Stale file handle: 'Data_.json'\n\n\nYou can suppress this exception and fall back to eager by setting:\n    import torch._dynamo\n    torch._dynamo.config.suppress_errors = True\n"
Arguments: ()
Traceback (most recent call last):
  File "/n/home07/hyitayew/Research/Summer 2023/experiments/Final_convolution_benchmark/100/script_0_114_100.py", line 83, in <module>
FileNotFoundError: [Errno 2] No such file or directory: '/n/home07/hyitayew/Research/Summer 2023/experiments/Final_convolution_benchmark/100/script_0_114_100.py'
--- Logging error ---
Traceback (most recent call last):
  File "/n/home07/hyitayew/source_env/lib/python3.10/site-packages/concurrent_log_handler/__init__.py", line 293, in atomic_open
    file = open(file_path, "r+", encoding=self.encoding, newline=self.newline)
FileNotFoundError: [Errno 2] No such file or directory: '/n/home07/hyitayew/Research/Summer 2023/experiments/Final_convolution_benchmark/100/.__benchmark_convolution.lock'

During handling of the above exception, another exception occurred:

Traceback (most recent call last):
  File "/n/home07/hyitayew/source_env/lib/python3.10/site-packages/concurrent_log_handler/__init__.py", line 382, in emit
    self._do_lock()
  File "/n/home07/hyitayew/source_env/lib/python3.10/site-packages/concurrent_log_handler/__init__.py", line 434, in _do_lock
    self._open_lockfile()
  File "/n/home07/hyitayew/source_env/lib/python3.10/site-packages/concurrent_log_handler/__init__.py", line 286, in _open_lockfile
    self.stream_lock = self.atomic_open(lock_file)
  File "/n/home07/hyitayew/source_env/lib/python3.10/site-packages/concurrent_log_handler/__init__.py", line 297, in atomic_open
    fd = os.open(file_path, os.O_CREAT | os.O_EXCL | os.O_RDWR)
FileNotFoundError: [Errno 2] No such file or directory: '/n/home07/hyitayew/Research/Summer 2023/experiments/Final_convolution_benchmark/100/.__benchmark_convolution.lock'
Call stack:
  File "/n/home07/hyitayew/Research/Summer 2023/experiments/Final_convolution_benchmark/100/../benchmark.py", line 71, in <module>
  File "/n/home07/hyitayew/Research/Summer 2023/experiments/Final_convolution_benchmark/utils.py", line 102, in run_script
    logger.info(f"Finished running script_{gpu}_{i}_{division}")
  File "/n/home07/hyitayew/source_env/lib/python3.10/logging/__init__.py", line 1477, in info
    self._log(INFO, msg, args, **kwargs)
  File "/n/home07/hyitayew/source_env/lib/python3.10/logging/__init__.py", line 1624, in _log
    self.handle(record)
  File "/n/home07/hyitayew/source_env/lib/python3.10/logging/__init__.py", line 1634, in handle
    self.callHandlers(record)
  File "/n/home07/hyitayew/source_env/lib/python3.10/logging/__init__.py", line 1696, in callHandlers
    hdlr.handle(record)
  File "/n/home07/hyitayew/source_env/lib/python3.10/logging/__init__.py", line 968, in handle
    self.emit(record)
  File "/n/home07/hyitayew/source_env/lib/python3.10/site-packages/concurrent_log_handler/__init__.py", line 400, in emit
    self.handleError(record)
Message: 'Finished running script_0_114_100'
Arguments: ()
  0%|          | 115/101547 [04:44<157:19:43,  5.58s/it]--- Logging error ---
Traceback (most recent call last):
  File "/n/home07/hyitayew/source_env/lib/python3.10/site-packages/concurrent_log_handler/__init__.py", line 293, in atomic_open
    file = open(file_path, "r+", encoding=self.encoding, newline=self.newline)
FileNotFoundError: [Errno 2] No such file or directory: '/n/home07/hyitayew/Research/Summer 2023/experiments/Final_convolution_benchmark/100/.__benchmark_convolution.lock'

During handling of the above exception, another exception occurred:

Traceback (most recent call last):
  File "/n/home07/hyitayew/source_env/lib/python3.10/site-packages/concurrent_log_handler/__init__.py", line 382, in emit
    self._do_lock()
  File "/n/home07/hyitayew/source_env/lib/python3.10/site-packages/concurrent_log_handler/__init__.py", line 434, in _do_lock
    self._open_lockfile()
  File "/n/home07/hyitayew/source_env/lib/python3.10/site-packages/concurrent_log_handler/__init__.py", line 286, in _open_lockfile
    self.stream_lock = self.atomic_open(lock_file)
  File "/n/home07/hyitayew/source_env/lib/python3.10/site-packages/concurrent_log_handler/__init__.py", line 297, in atomic_open
    fd = os.open(file_path, os.O_CREAT | os.O_EXCL | os.O_RDWR)
FileNotFoundError: [Errno 2] No such file or directory: '/n/home07/hyitayew/Research/Summer 2023/experiments/Final_convolution_benchmark/100/.__benchmark_convolution.lock'
Call stack:
  File "/n/home07/hyitayew/Research/Summer 2023/experiments/Final_convolution_benchmark/100/../benchmark.py", line 67, in <module>
  File "/n/home07/hyitayew/source_env/lib/python3.10/logging/__init__.py", line 1477, in info
    self._log(INFO, msg, args, **kwargs)
  File "/n/home07/hyitayew/source_env/lib/python3.10/logging/__init__.py", line 1624, in _log
    self.handle(record)
  File "/n/home07/hyitayew/source_env/lib/python3.10/logging/__init__.py", line 1634, in handle
    self.callHandlers(record)
  File "/n/home07/hyitayew/source_env/lib/python3.10/logging/__init__.py", line 1696, in callHandlers
    hdlr.handle(record)
  File "/n/home07/hyitayew/source_env/lib/python3.10/logging/__init__.py", line 968, in handle
    self.emit(record)
  File "/n/home07/hyitayew/source_env/lib/python3.10/site-packages/concurrent_log_handler/__init__.py", line 400, in emit
    self.handleError(record)
Message: 'Skipping invalid group: 2. In Channels: 5'
Arguments: ()
--- Logging error ---
Traceback (most recent call last):
  File "/n/home07/hyitayew/source_env/lib/python3.10/site-packages/concurrent_log_handler/__init__.py", line 293, in atomic_open
    file = open(file_path, "r+", encoding=self.encoding, newline=self.newline)
FileNotFoundError: [Errno 2] No such file or directory: '/n/home07/hyitayew/Research/Summer 2023/experiments/Final_convolution_benchmark/100/.__benchmark_convolution.lock'

During handling of the above exception, another exception occurred:

Traceback (most recent call last):
  File "/n/home07/hyitayew/source_env/lib/python3.10/site-packages/concurrent_log_handler/__init__.py", line 382, in emit
    self._do_lock()
  File "/n/home07/hyitayew/source_env/lib/python3.10/site-packages/concurrent_log_handler/__init__.py", line 434, in _do_lock
    self._open_lockfile()
  File "/n/home07/hyitayew/source_env/lib/python3.10/site-packages/concurrent_log_handler/__init__.py", line 286, in _open_lockfile
    self.stream_lock = self.atomic_open(lock_file)
  File "/n/home07/hyitayew/source_env/lib/python3.10/site-packages/concurrent_log_handler/__init__.py", line 297, in atomic_open
    fd = os.open(file_path, os.O_CREAT | os.O_EXCL | os.O_RDWR)
FileNotFoundError: [Errno 2] No such file or directory: '/n/home07/hyitayew/Research/Summer 2023/experiments/Final_convolution_benchmark/100/.__benchmark_convolution.lock'
Call stack:
  File "/n/home07/hyitayew/Research/Summer 2023/experiments/Final_convolution_benchmark/100/../benchmark.py", line 67, in <module>
  File "/n/home07/hyitayew/source_env/lib/python3.10/logging/__init__.py", line 1477, in info
    self._log(INFO, msg, args, **kwargs)
  File "/n/home07/hyitayew/source_env/lib/python3.10/logging/__init__.py", line 1624, in _log
    self.handle(record)
  File "/n/home07/hyitayew/source_env/lib/python3.10/logging/__init__.py", line 1634, in handle
    self.callHandlers(record)
  File "/n/home07/hyitayew/source_env/lib/python3.10/logging/__init__.py", line 1696, in callHandlers
    hdlr.handle(record)
  File "/n/home07/hyitayew/source_env/lib/python3.10/logging/__init__.py", line 968, in handle
    self.emit(record)
  File "/n/home07/hyitayew/source_env/lib/python3.10/site-packages/concurrent_log_handler/__init__.py", line 400, in emit
    self.handleError(record)
Message: 'Skipping invalid group: 3. In Channels: 5'
Arguments: ()
--- Logging error ---
Traceback (most recent call last):
  File "/n/home07/hyitayew/source_env/lib/python3.10/site-packages/concurrent_log_handler/__init__.py", line 293, in atomic_open
    file = open(file_path, "r+", encoding=self.encoding, newline=self.newline)
FileNotFoundError: [Errno 2] No such file or directory: '/n/home07/hyitayew/Research/Summer 2023/experiments/Final_convolution_benchmark/100/.__benchmark_convolution.lock'

During handling of the above exception, another exception occurred:

Traceback (most recent call last):
  File "/n/home07/hyitayew/source_env/lib/python3.10/site-packages/concurrent_log_handler/__init__.py", line 382, in emit
    self._do_lock()
  File "/n/home07/hyitayew/source_env/lib/python3.10/site-packages/concurrent_log_handler/__init__.py", line 434, in _do_lock
    self._open_lockfile()
  File "/n/home07/hyitayew/source_env/lib/python3.10/site-packages/concurrent_log_handler/__init__.py", line 286, in _open_lockfile
    self.stream_lock = self.atomic_open(lock_file)
  File "/n/home07/hyitayew/source_env/lib/python3.10/site-packages/concurrent_log_handler/__init__.py", line 297, in atomic_open
    fd = os.open(file_path, os.O_CREAT | os.O_EXCL | os.O_RDWR)
FileNotFoundError: [Errno 2] No such file or directory: '/n/home07/hyitayew/Research/Summer 2023/experiments/Final_convolution_benchmark/100/.__benchmark_convolution.lock'
Call stack:
  File "/n/home07/hyitayew/Research/Summer 2023/experiments/Final_convolution_benchmark/100/../benchmark.py", line 67, in <module>
  File "/n/home07/hyitayew/source_env/lib/python3.10/logging/__init__.py", line 1477, in info
    self._log(INFO, msg, args, **kwargs)
  File "/n/home07/hyitayew/source_env/lib/python3.10/logging/__init__.py", line 1624, in _log
    self.handle(record)
  File "/n/home07/hyitayew/source_env/lib/python3.10/logging/__init__.py", line 1634, in handle
    self.callHandlers(record)
  File "/n/home07/hyitayew/source_env/lib/python3.10/logging/__init__.py", line 1696, in callHandlers
    hdlr.handle(record)
  File "/n/home07/hyitayew/source_env/lib/python3.10/logging/__init__.py", line 968, in handle
    self.emit(record)
  File "/n/home07/hyitayew/source_env/lib/python3.10/site-packages/concurrent_log_handler/__init__.py", line 400, in emit
    self.handleError(record)
Message: 'Skipping invalid group: 4. In Channels: 5'
Arguments: ()
  0%|          | 118/101547 [04:44<67:59:18,  2.41s/it] 
Traceback (most recent call last):
  File "/n/home07/hyitayew/Research/Summer 2023/experiments/Final_convolution_benchmark/100/../benchmark.py", line 71, in <module>
    if out_channels % group != 0:
  File "/n/home07/hyitayew/Research/Summer 2023/experiments/Final_convolution_benchmark/utils.py", line 11, in run_script
    with open(f'script_{gpu}_{i}_{division}.py', 'w') as f:
OSError: [Errno 116] Stale file handle: 'script_0_118_100.py'
